<?xml version="1.0" encoding="utf-8"?>
<!-- =================================================================================== -->
<!-- |    This document was autogenerated by xacro from my_robot_integration.urdf.xacro | -->
<!-- |    EDITING THIS FILE BY HAND IS NOT RECOMMENDED                                 | -->
<!-- =================================================================================== -->
<!-- Name your robot here -->
<robot name="delivery_car">
  <link name="dummy_link">
    <pose>0 0 0 0 0 0 </pose>
  </link>
  <joint name="dummy_joint" type="fixed">
    <parent link="dummy_link"/>
    <child link="base_link"/>
  </joint>
  <link name="base_link">
    <inertial>
      <origin rpy="0 0 0" xyz="-0.000908154363345622 -6.56623908190518E-10 0.293045389307219"/>
      <mass value="72.3574570918659"/>
      <inertia ixx="2.70857432269713" ixy="9.07816692403917E-08" ixz="-0.00713957051532295" iyy="6.90075895867942" iyz="-1.12917933798358E-09" izz="7.72228876783316"/>
    </inertial>
    <visual>
      <origin rpy="0 0 0" xyz="0 0 0"/>
      <geometry>
        <mesh filename="package://delivery_car/meshes/base_link.STL"/>
      </geometry>
      <material name="">
        <color rgba="1 1 1 1"/>
      </material>
    </visual>
    <collision>
      <origin rpy="0 0 0" xyz="0 0 0"/>
      <geometry>
        <mesh filename="package://delivery_car/meshes/base_link.STL"/>
      </geometry>
    </collision>
  </link>
  <link name="right_front_lmount">
    <inertial>
      <origin rpy="0 0 0" xyz="0 0.0300195937636138 -0.109244446855341"/>
      <mass value="0.0482027103305475"/>
      <inertia ixx="0.000190477781556076" ixy="-1.68743442594918E-20" ixz="-1.95935218617135E-20" iyy="0.000152318699141993" iyz="8.88301056256031E-06" izz="3.93305161229015E-05"/>
    </inertial>
    <visual>
      <origin rpy="0 0 0" xyz="0 0 0"/>
      <geometry>
        <mesh filename="package://delivery_car/meshes/right_front_lmount.STL"/>
      </geometry>
      <material name="">
        <color rgba="0.666666666666667 0.698039215686274 0.768627450980392 1"/>
      </material>
    </visual>
    <collision>
      <origin rpy="0 0 0" xyz="0 0 0"/>
      <geometry>
        <mesh filename="package://delivery_car/meshes/right_front_lmount.STL"/>
      </geometry>
    </collision>
  </link>
  <joint name="right_front_turn_joint" type="continuous">
    <origin rpy="0 0 0" xyz="0.254 -0.2159 0.2794"/>
    <parent link="base_link"/>
    <child link="right_front_lmount"/>
    <axis xyz="0 0 -1"/>
  </joint>
  <link name="right_front_wheel">
    <inertial>
      <origin rpy="0 0 0" xyz="-9.99200722162641E-16 -5.89218730291041E-16 -0.0380999999999998"/>
      <mass value="1.91896102163701"/>
      <inertia ixx="0.00592697643071667" ixy="6.03510974918702E-18" ixz="1.08485252691956E-17" iyy="0.00592697643071669" iyz="3.5499627630916E-17" izz="0.0100412541412463"/>
    </inertial>
    <visual>
      <origin rpy="0 0 0" xyz="0 0 0"/>
      <geometry>
        <mesh filename="package://delivery_car/meshes/right_front_wheel.STL"/>
      </geometry>
      <material name="">
        <color rgba="0.298039215686275 0.298039215686275 0.298039215686275 1"/>
      </material>
    </visual>
    <collision>
      <origin rpy="0 0 0" xyz="0 0 0"/>
      <geometry>
        <mesh filename="package://delivery_car/meshes/right_front_wheel.STL"/>
      </geometry>
    </collision>
  </link>
  <joint name="right_front_wheel_joint" type="continuous">
    <origin rpy="1.5707963267949 0 0" xyz="0 -0.0381000000000009 -0.1778"/>
    <parent link="right_front_lmount"/>
    <child link="right_front_wheel"/>
    <axis xyz="0 0 -1"/>
  </joint>
  <link name="left_front_lmount">
    <inertial>
      <origin rpy="0 0 0" xyz="0 -0.0300195937636138 -0.109244446855341"/>
      <mass value="0.0482027103305475"/>
      <inertia ixx="0.000190477781556076" ixy="9.16464545695675E-21" ixz="7.34420579718887E-21" iyy="0.000152318699141993" iyz="-8.8830105625603E-06" izz="3.93305161229015E-05"/>
    </inertial>
    <visual>
      <origin rpy="0 0 0" xyz="0 0 0"/>
      <geometry>
        <mesh filename="package://delivery_car/meshes/left_front_lmount.STL"/>
      </geometry>
      <material name="">
        <color rgba="0.666666666666667 0.698039215686274 0.768627450980392 1"/>
      </material>
    </visual>
    <collision>
      <origin rpy="0 0 0" xyz="0 0 0"/>
      <geometry>
        <mesh filename="package://delivery_car/meshes/left_front_lmount.STL"/>
      </geometry>
    </collision>
  </link>
  <joint name="left_front_turn_joint" type="continuous">
    <origin rpy="0 0 0" xyz="0.254 0.2159 0.2794"/>
    <parent link="base_link"/>
    <child link="left_front_lmount"/>
    <axis xyz="0 0 -1"/>
  </joint>
  <link name="left_front_wheel">
    <inertial>
      <origin rpy="0 0 0" xyz="2.55351295663786E-15 7.09428925892797E-16 -0.0381000000000029"/>
      <mass value="1.91896102163701"/>
      <inertia ixx="0.00592697643071667" ixy="-6.03510974918702E-18" ixz="-1.08520018619747E-17" iyy="0.00592697643071669" iyz="3.55032540074801E-17" izz="0.0100412541412463"/>
    </inertial>
    <visual>
      <origin rpy="0 0 0" xyz="0 0 0"/>
      <geometry>
        <mesh filename="package://delivery_car/meshes/left_front_wheel.STL"/>
      </geometry>
      <material name="">
        <color rgba="0.298039215686275 0.298039215686275 0.298039215686275 1"/>
      </material>
    </visual>
    <collision>
      <origin rpy="0 0 0" xyz="0 0 0"/>
      <geometry>
        <mesh filename="package://delivery_car/meshes/left_front_wheel.STL"/>
      </geometry>
    </collision>
  </link>
  <joint name="left_front_wheel_joint" type="continuous">
    <origin rpy="-1.5707963267949 0 0" xyz="0 0.0381 -0.1778"/>
    <parent link="left_front_lmount"/>
    <child link="left_front_wheel"/>
    <axis xyz="0 0 1"/>
  </joint>
  <link name="right_rear_lmount">
    <inertial>
      <origin rpy="0 0 0" xyz="0 0.0300195937636138 -0.109244446855341"/>
      <mass value="0.0482027103305474"/>
      <inertia ixx="0.000190477781556076" ixy="3.67941101261918E-21" ixz="-1.03250959627839E-20" iyy="0.000152318699141993" iyz="8.8830105625603E-06" izz="3.93305161229015E-05"/>
    </inertial>
    <visual>
      <origin rpy="0 0 0" xyz="0 0 0"/>
      <geometry>
        <mesh filename="package://delivery_car/meshes/right_rear_lmount.STL"/>
      </geometry>
      <material name="">
        <color rgba="0.666666666666667 0.698039215686274 0.768627450980392 1"/>
      </material>
    </visual>
    <collision>
      <origin rpy="0 0 0" xyz="0 0 0"/>
      <geometry>
        <mesh filename="package://delivery_car/meshes/right_rear_lmount.STL"/>
      </geometry>
    </collision>
  </link>
  <joint name="right_rear_turn_joint" type="fixed">
    <origin rpy="0 0 0" xyz="-0.254 -0.2159 0.2794"/>
    <parent link="base_link"/>
    <child link="right_rear_lmount"/>
    <axis xyz="0 0 0"/>
  </joint>
  <link name="right_rear_wheel">
    <inertial>
      <origin rpy="0 0 0" xyz="-5.55111512312578E-17 -5.54090920996416E-16 -0.0380999999999997"/>
      <mass value="1.91896102163701"/>
      <inertia ixx="0.00592697643071667" ixy="5.92923063078023E-18" ixz="1.08314104781147E-17" iyy="0.00592697643071669" iyz="3.55269520084078E-17" izz="0.0100412541412463"/>
    </inertial>
    <visual>
      <origin rpy="0 0 0" xyz="0 0 0"/>
      <geometry>
        <mesh filename="package://delivery_car/meshes/right_rear_wheel.STL"/>
      </geometry>
      <material name="">
        <color rgba="0.298039215686275 0.298039215686275 0.298039215686275 1"/>
      </material>
    </visual>
    <collision>
      <origin rpy="0 0 0" xyz="0 0 0"/>
      <geometry>
        <mesh filename="package://delivery_car/meshes/right_rear_wheel.STL"/>
      </geometry>
    </collision>
  </link>
  <joint name="right_rear_wheel_joint" type="continuous">
    <origin rpy="1.5707963267949 0 0" xyz="0 -0.0380999999999991 -0.1778"/>
    <parent link="right_rear_lmount"/>
    <child link="right_rear_wheel"/>
    <axis xyz="0 0 1"/>
  </joint>
  <link name="left_rear_lmount">
    <inertial>
      <origin rpy="0 0 0" xyz="0 -0.0300195937636138 -0.109244446855341"/>
      <mass value="0.0482027103305474"/>
      <inertia ixx="0.000190477781556075" ixy="-9.83478221577053E-21" ixz="1.27384349973246E-20" iyy="0.000152318699141993" iyz="-8.88301056256029E-06" izz="3.93305161229015E-05"/>
    </inertial>
    <visual>
      <origin rpy="0 0 0" xyz="0 0 0"/>
      <geometry>
        <mesh filename="package://delivery_car/meshes/left_rear_lmount.STL"/>
      </geometry>
      <material name="">
        <color rgba="0.666666666666667 0.698039215686274 0.768627450980392 1"/>
      </material>
    </visual>
    <collision>
      <origin rpy="0 0 0" xyz="0 0 0"/>
      <geometry>
        <mesh filename="package://delivery_car/meshes/left_rear_lmount.STL"/>
      </geometry>
    </collision>
  </link>
  <joint name="left_rear_turn_joint" type="fixed">
    <origin rpy="0 0 0" xyz="-0.254 0.2159 0.2794"/>
    <parent link="base_link"/>
    <child link="left_rear_lmount"/>
    <axis xyz="0 0 0"/>
  </joint>
  <link name="left_rear_wheel">
    <inertial>
      <origin rpy="0 0 0" xyz="-1.11022302462516E-16 5.59504140230176E-16 -0.0380999999999976"/>
      <mass value="1.91896102163701"/>
      <inertia ixx="0.00592697643071667" ixy="-5.79522737154664E-18" ixz="-1.09550633570143E-17" iyy="0.00592697643071669" iyz="3.549478657157E-17" izz="0.0100412541412463"/>
    </inertial>
    <visual>
      <origin rpy="0 0 0" xyz="0 0 0"/>
      <geometry>
        <mesh filename="package://delivery_car/meshes/left_rear_wheel.STL"/>
      </geometry>
      <material name="">
        <color rgba="0.298039215686275 0.298039215686275 0.298039215686275 1"/>
      </material>
    </visual>
    <collision>
      <origin rpy="0 0 0" xyz="0 0 0"/>
      <geometry>
        <mesh filename="package://delivery_car/meshes/left_rear_wheel.STL"/>
      </geometry>
    </collision>
  </link>
  <joint name="left_rear_wheel_joint" type="continuous">
    <origin rpy="-1.5707963267949 0 0" xyz="0 0.0381 -0.1778"/>
    <parent link="left_rear_lmount"/>
    <child link="left_rear_wheel"/>
    <axis xyz="0 0 -1"/>
  </joint>
  <transmission name="right_rear_wheel_trans">
    <type>transmission_interface/SimpleTransmission</type>
    <joint name="right_rear_wheel_joint">
      <hardwareInterface>hardware_interface/VelocityJointInterface</hardwareInterface>
    </joint>
    <actuator name="right_rear_wheel_motor">
      <hardwareInterface>hardware_interface/VelocityJointInterface</hardwareInterface>
      <mechanicalReduction>1</mechanicalReduction>
    </actuator>
  </transmission>
  <transmission name="left_rear_wheel_trans">
    <type>transmission_interface/SimpleTransmission</type>
    <joint name="left_rear_wheel_joint">
      <hardwareInterface>hardware_interface/VelocityJointInterface</hardwareInterface>
    </joint>
    <actuator name="left_rear_wheel_motor">
      <hardwareInterface>hardware_interface/VelocityJointInterface</hardwareInterface>
      <mechanicalReduction>1</mechanicalReduction>
    </actuator>
  </transmission>
  <transmission name="right_front_turn_trans">
    <type>transmission_interface/SimpleTransmission</type>
    <joint name="right_front_turn_joint">
      <hardwareInterface>hardware_interface/EffortJointInterface</hardwareInterface>
    </joint>
    <actuator name="right_front_turn_motor">
      <hardwareInterface>hardware_interface/EffortJointInterface</hardwareInterface>
      <mechanicalReduction>1</mechanicalReduction>
    </actuator>
  </transmission>
  <transmission name="left_front_turn_trans">
    <type>transmission_interface/SimpleTransmission</type>
    <joint name="left_front_turn_joint">
      <hardwareInterface>hardware_interface/EffortJointInterface</hardwareInterface>
    </joint>
    <actuator name="left_front_turn_motor">
      <hardwareInterface>hardware_interface/EffortJointInterface</hardwareInterface>
      <mechanicalReduction>1</mechanicalReduction>
    </actuator>
  </transmission>
  <link name="base_laser">
    <inertial>
      <origin rpy="0 0 0" xyz="-0.00029774 0.0066667 0.00013047"/>
      <mass value="0.15717"/>
      <inertia ixx="6.7885E-05" ixy="-1.3987E-07" ixz="-8.1554E-07" iyy="0.00013173" iyz="-9.0932E-08" izz="7.1972E-05"/>
    </inertial>
    <visual>
      <origin rpy="0 0 0" xyz="0 0 0"/>
      <geometry>
        <mesh filename="package://ydlidar_ros/meshes/ydlidar.dae"/>
      </geometry>
      <material name="">
        <color rgba="0.64706 0.61961 0.58824 1"/>
      </material>
    </visual>
    <collision>
      <origin rpy="0 0 0" xyz="0 0 0"/>
      <geometry>
        <mesh filename="package://ydlidar_ros/meshes/ydlidar.dae"/>
      </geometry>
    </collision>
  </link>
  <link name="laser_frame">
    <inertial>
      <origin rpy="0 0 0" xyz="-0.00036659 0.00064155 -0.00027052"/>
      <mass value="0.25482"/>
      <inertia ixx="8.9194E-05" ixy="1.8116E-07" ixz="3.6435E-08" iyy="0.00018279" iyz="2.423E-07" izz="0.00011103"/>
    </inertial>
    <!--visual>
      <origin
        xyz="0 0 0"
        rpy="0 0 0" />
      <geometry>
        <mesh
          filename="package://ydlidar_ros/meshes/ydlidar.dae" />
      </geometry>
      <material
        name="">
        <color
          rgba="0.64706 0.61961 0.58824 1" />
      </material>
    </visual-->
    <!--collision>
      <origin
        xyz="0 0 0"
        rpy="0 0 0" />
      <geometry>
        <mesh
          filename="package://ydlidar_ros/meshes/ydlidar.dae" />
      </geometry>
    </collision-->
  </link>
  <joint name="laser_joint" type="fixed">
    <origin rpy="0 0 0" xyz="0 0 0.03172"/>
    <parent link="base_laser"/>
    <child link="laser_frame"/>
    <axis xyz="0 0 0"/>
  </joint>
  <!-- Add your gazebo sensors here -->
  <gazebo reference="base_laser">
    <!-- <gravity>true</gravity> -->
    <!-- Gazebo has fixed set of Sensors types. Check them out here <> -->
    <sensor name="laser" type="ray">
      <!-- Add in your sensor characteristics -->
      <pose> 0 0 0 0 0 0 </pose>
      <visualise>true</visualise>
      <update_rate>40</update_rate>
      <always_on>true</always_on>
      <ray>
        <scan>
          <horizontal>
            <samples>720</samples>
            <resolution>1</resolution>
            <min_angle>-1.570796</min_angle>
            <max_angle>1.570796</max_angle>
          </horizontal>
        </scan>
        <range>
          <min>0.10</min>
          <max>30.0</max>
          <resolution>0.01</resolution>
        </range>
        <noise>
          <type>gaussian</type>
          <mean>0.0</mean>
          <stddev>0.01</stddev>
        </noise>
      </ray>
      <plugin filename="libgazebo_ros_laser.so" name="gazebo_ros_head_hokuyo_controller">
        <!-- Use topic name as /my_robot/scan -->
        <topicName>/delivery_car/scan</topicName>
        <frameName>laser_frame</frameName>
      </plugin>
    </sensor>
  </gazebo>
  <!--  Gazebo plugin for control here is already added for you -->
  <gazebo>
    <plugin filename="libgazebo_ros_control.so" name="gazebo_ros_control">
      <robotNamespace>/delivery_car</robotNamespace>
      <robotSimType>gazebo_ros_control/DefaultRobotHWSim</robotSimType>
      <legacyModeNS>true</legacyModeNS>
    </plugin>
  </gazebo>
  <!-- Create a joint between your robot and sensor -->
  <joint name="lirobo_joint" type="fixed">
    <axis xyz="0 0 1"/>
    <origin rpy="0 0 0" xyz="0 0 0.534"/>
    <parent link="base_link"/>
    <child link="base_laser"/>
  </joint>
</robot>
