<?xml version="1.0" encoding="utf-8"?>
<!-- This URDF was automatically created by SolidWorks to URDF Exporter! Originally created by Stephen Brawner (brawner@gmail.com) 
     Commit Version: 1.6.0-1-g15f4949  Build Version: 1.6.7594.29634
     For more information, please see http://wiki.ros.org/sw_urdf_exporter -->
<robot
  name="delivery_car">
  
  <link name="dummy_link">
    <pose>0 0 0 0 0 0 </pose>
  </link>
  <joint name="dummy_joint" type="fixed">
    <parent link="dummy_link" />
    <child link="base_link" />
  </joint>

  <link name="base_link">
    <inertial>
      <origin
        xyz="-0.000908154363345622 -6.56623908190518E-10 0.293045389307219"
        rpy="0 0 0" />
      <mass
        value="32.3574570918659" />
      <!-- <inertia
        ixx="2.70857432269713"
        ixy="0.00"
        ixz="-0.00713957051532295"
        iyy="6.90075895867942"
        iyz="0.00"
        izz="7.72228876783316" /> -->
      <inertia
        ixx="2.70857432269713"
        ixy="9.07816692403917E-08"
        ixz="-0.00713957051532295"
        iyy="6.90075895867942"
        iyz="-1.12917933798358E-09"
        izz="7.72228876783316" />
    </inertial>
    <visual>
      <origin
        xyz="0 0 0"
        rpy="0 0 0" />
      <geometry>
        <mesh
          filename="package://delivery_car/meshes/base_link.STL" />
      </geometry>
      <material
        name="">
        <color
          rgba="1 1 1 1" />
      </material>
    </visual>
    <collision>
      <origin
        xyz="0 0 0"
        rpy="0 0 0" />
      <geometry>
        <mesh
          filename="package://delivery_car/meshes/base_link.STL" />
      </geometry>
    </collision>
  </link>
  <link
    name="right_front_lmount">
    <inertial>
      <origin
        xyz="0 0.0300195937636138 -0.109244446855341"
        rpy="0 0 0" />
      <mass
        value="0.0482027103305475" />
      <!-- <inertia
        ixx="0.000190477781556076"
        ixy="0.00"
        ixz="0.00"
        iyy="0.000152318699141993"
        iyz="0.00"
        izz="0.0001" /> -->
      <inertia
        ixx="0.000190477781556076"
        ixy="-1.68743442594918E-20"
        ixz="-1.95935218617135E-20"
        iyy="0.000152318699141993"
        iyz="8.88301056256031E-06"
        izz="3.93305161229015E-05" />
    </inertial>
    <visual>
      <origin
        xyz="0 0 0"
        rpy="0 0 0" />
      <geometry>
        <mesh
          filename="package://delivery_car/meshes/right_front_lmount.STL" />
      </geometry>
      <material
        name="">
        <color
          rgba="0.666666666666667 0.698039215686274 0.768627450980392 1" />
      </material>
    </visual>
    <collision>
      <origin
        xyz="0 0 0"
        rpy="0 0 0" />
      <geometry>
        <mesh
          filename="package://delivery_car/meshes/right_front_lmount.STL" />
      </geometry>
    </collision>
  </link>

  <!-- <joint
    name="right_front_turn_joint"
    type="continuous">
    <origin
      xyz="0.254 -0.2159 0.2794"
      rpy="0 0 0" />
    <parent
      link="base_link" />
    <child
      link="right_front_lmount" />
    <axis
      xyz="0 0 -1" />
  </joint> -->
  
  <joint name="right_front_turn_joint" type="revolute">
    <axis xyz="0 0 -1"/>
    <limit effort="1.0" lower="-0.5" upper="0.5" velocity="20.0"/>
    <origin rpy="0 0 0" xyz="0.254 -0.2159 0.2794"/>
    <parent link="base_link"/>
    <child link="right_front_lmount"/>
  </joint>

  <link
    name="right_front_wheel">
    <inertial>
      <origin
        xyz="-9.99200722162641E-16 -5.89218730291041E-16 -0.0380999999999998"
        rpy="0 0 0" />
      <mass
        value="1.91896102163701" />
      <!-- <inertia
        ixx="0.00592697643071667"
        ixy="0.00"
        ixz="0.00"
        iyy="0.00592697643071669"
        iyz="0.00"
        izz="0.0100412541412463" /> -->
      <inertia
        ixx="0.00592697643071667"
        ixy="6.03510974918702E-18"
        ixz="1.08485252691956E-17"
        iyy="0.00592697643071669"
        iyz="3.5499627630916E-17"
        izz="0.01" />
    </inertial>
    <visual>
      <origin
        xyz="0 0 0"
        rpy="0 0 0" />
      <geometry>
        <mesh
          filename="package://delivery_car/meshes/right_front_wheel.STL" />
      </geometry>
      <material
        name="">
        <color
          rgba="0.298039215686275 0.298039215686275 0.298039215686275 1" />
      </material>
    </visual>
    <collision>
      <origin
        xyz="0 0 0"
        rpy="0 0 0" />
      <geometry>
        <mesh
          filename="package://delivery_car/meshes/right_front_wheel.STL" />
      </geometry>
    </collision>
  </link>

  <joint
    name="right_front_wheel_joint"
    type="continuous">
    <origin
      xyz="0 -0.0381000000000009 -0.1778"
      rpy="1.5707963267949 0 0" />
    <parent
      link="right_front_lmount" />
    <child
      link="right_front_wheel" />
    <axis
      xyz="0 0 -1" />
  </joint>

  <!-- <joint name="right_front_wheel_joint" type="revolute">
    <axis xyz="0 0 -1"/>
    <limit effort="1000.0" velocity="20.0"/>
    <origin rpy="1.5707963267949 0 0" xyz="0 -0.0381000000000009 -0.1778"/>
    <parent link="right_front_lmount"/>
    <child link="right_front_wheel"/>
  </joint> -->

  <link
    name="left_front_lmount">
    <inertial>
      <origin
        xyz="0 -0.0300195937636138 -0.109244446855341"
        rpy="0 0 0" />
      <mass
        value="0.0482027103305475" />
      <!-- <inertia
        ixx="0.000190477781556076"
        ixy="0.00"
        ixz="0.00"
        iyy="0.000152318699141993"
        iyz="0.00"
        izz="0.0001" /> -->
      <inertia
        ixx="0.000190477781556076"
        ixy="9.16464545695675E-21"
        ixz="7.34420579718887E-21"
        iyy="0.000152318699141993"
        iyz="-8.8830105625603E-06"
        izz="3.93305161229015E-05" />
    </inertial>
    <visual>
      <origin
        xyz="0 0 0"
        rpy="0 0 0" />
      <geometry>
        <mesh
          filename="package://delivery_car/meshes/left_front_lmount.STL" />
      </geometry>
      <material
        name="">
        <color
          rgba="0.666666666666667 0.698039215686274 0.768627450980392 1" />
      </material>
    </visual>
    <collision>
      <origin
        xyz="0 0 0"
        rpy="0 0 0" />
      <geometry>
        <mesh
          filename="package://delivery_car/meshes/left_front_lmount.STL" />
      </geometry>
    </collision>
  </link>

  <!-- <joint
    name="left_front_turn_joint"
    type="continuous">
    <origin
      xyz="0.254 0.2159 0.2794"
      rpy="0 0 0" />
    <parent
      link="base_link" />
    <child
      link="left_front_lmount" />
    <axis
      xyz="0 0 -1" />
  </joint> -->

  <joint name="left_front_turn_joint" type="revolute">
    <axis xyz="0 0 -1"/>
    <limit effort="1.0" lower="-0.5" upper="0.5" velocity="20.0"/>
    <origin rpy="0 0 0" xyz="0.254 0.2159 0.2794"/>
    <parent link="base_link"/>
    <child link="left_front_lmount"/>
  </joint>

  <link
    name="left_front_wheel">
    <inertial>
      <origin
        xyz="2.55351295663786E-15 7.09428925892797E-16 -0.0381000000000029"
        rpy="0 0 0" />
      <mass
        value="1.91896102163701" />
      <!-- <inertia
        ixx="0.00592697643071667"
        ixy="0.00"
        ixz="0.00"
        iyy="0.00592697643071669"
        iyz="0.00"
        izz="0.0100412541412463" /> -->
      <inertia
        ixx="0.00592697643071667"
        ixy="-6.03510974918702E-18"
        ixz="-1.08520018619747E-17"
        iyy="0.00592697643071669"
        iyz="3.55032540074801E-17"
        izz="0.0100412541412463" />
    </inertial>
    <visual>
      <origin
        xyz="0 0 0"
        rpy="0 0 0" />
      <geometry>
        <mesh
          filename="package://delivery_car/meshes/left_front_wheel.STL" />
      </geometry>
      <material
        name="">
        <color
          rgba="0.298039215686275 0.298039215686275 0.298039215686275 1" />
      </material>
    </visual>
    <collision>
      <origin
        xyz="0 0 0"
        rpy="0 0 0" />
      <geometry>
        <mesh
          filename="package://delivery_car/meshes/left_front_wheel.STL" />
      </geometry>
    </collision>
  </link>

  <joint
    name="left_front_wheel_joint"
    type="continuous">
    <origin
      xyz="0 0.0381 -0.1778"
      rpy="-1.5707963267949 0 0" />
    <parent
      link="left_front_lmount" />
    <child
      link="left_front_wheel" />
    <axis
      xyz="0 0 1" />
  </joint>

  <!-- <joint name="left_front_wheel_joint" type="revolute">
    <axis xyz="0 0 1"/>
    <limit effort="1000.0" velocity="20.0"/>
    <origin rpy="-1.5707963267949 0 0" xyz="0 0.0381 -0.1778"/>
    <parent link="left_front_lmount"/>
    <child link="left_front_wheel"/>
  </joint> -->

  <link
    name="right_rear_lmount">
    <inertial>
      <origin
        xyz="0 0.0300195937636138 -0.109244446855341"
        rpy="0 0 0" />
      <mass
        value="0.0482027103305474" />
      <!-- <inertia
        ixx="0.000190477781556076"
        ixy="0.00"
        ixz="0.00"
        iyy="0.000152318699141993"
        iyz="0.00"
        izz="0.0001" /> -->
      <inertia
        ixx="0.000190477781556076"
        ixy="3.67941101261918E-21"
        ixz="-1.03250959627839E-20"
        iyy="0.000152318699141993"
        iyz="8.8830105625603E-06"
        izz="3.93305161229015E-05" />
    </inertial>
    <visual>
      <origin
        xyz="0 0 0"
        rpy="0 0 0" />
      <geometry>
        <mesh
          filename="package://delivery_car/meshes/right_rear_lmount.STL" />
      </geometry>
      <material
        name="">
        <color
          rgba="0.666666666666667 0.698039215686274 0.768627450980392 1" />
      </material>
    </visual>
    <collision>
      <origin
        xyz="0 0 0"
        rpy="0 0 0" />
      <geometry>
        <mesh
          filename="package://delivery_car/meshes/right_rear_lmount.STL" />
      </geometry>
    </collision>
  </link>

  <joint
    name="right_rear_turn_joint"
    type="fixed">
    <origin
      xyz="-0.254 -0.2159 0.2794"
      rpy="0 0 0" />
    <parent
      link="base_link" />
    <child
      link="right_rear_lmount" />
    <axis
      xyz="0 0 0" />
  </joint>

  <link
    name="right_rear_wheel">
    <inertial>
      <origin
        xyz="-5.55111512312578E-17 -5.54090920996416E-16 -0.0380999999999997"
        rpy="0 0 0" />
      <mass
        value="1.91896102163701" />
      <!-- <inertia
        ixx="0.00592697643071667"
        ixy="0.00"
        ixz="0.00"
        iyy="0.00592697643071669"
        iyz="0.00"
        izz="0.0100412541412463" /> -->
      <inertia
        ixx="0.00592697643071667"
        ixy="5.92923063078023E-18"
        ixz="1.08314104781147E-17"
        iyy="0.00592697643071669"
        iyz="3.55269520084078E-17"
        izz="0.0100412541412463" />
    </inertial>
    <visual>
      <origin
        xyz="0 0 0"
        rpy="0 0 0" />
      <geometry>
        <mesh
          filename="package://delivery_car/meshes/right_rear_wheel.STL" />
      </geometry>
      <material
        name="">
        <color
          rgba="0.298039215686275 0.298039215686275 0.298039215686275 1" />
      </material>
    </visual>
    <collision>
      <origin
        xyz="0 0 0"
        rpy="0 0 0" />
      <geometry>
        <mesh
          filename="package://delivery_car/meshes/right_rear_wheel.STL" />
      </geometry>
    </collision>
  </link>

  <joint
    name="right_rear_wheel_joint"
    type="continuous">
    <origin
      xyz="0 -0.0380999999999991 -0.1778"
      rpy="1.5707963267949 0 0" />
    <parent
      link="right_rear_lmount" />
    <child
      link="right_rear_wheel" />
    <axis
      xyz="0 0 -1" />
  </joint>

  <!-- <joint name="right_rear_wheel_joint" type="revolute">
    <axis xyz="0 0 1"/>
    <limit effort="1000.0" velocity="20.0"/>
    <origin rpy="1.5707963267949 0 0" xyz="0 -0.0380999999999991 -0.1778"/>
    <parent link="right_rear_lmount"/>
    <child link="right_rear_wheel"/>
  </joint> -->

  <link
    name="left_rear_lmount">
    <inertial>
      <origin
        xyz="0 -0.0300195937636138 -0.109244446855341"
        rpy="0 0 0" />
      <mass
        value="0.0482027103305474" />
      <!-- <inertia
        ixx="0.000190477781556075"
        ixy="0.00"
        ixz="0.00"
        iyy="0.000152318699141993"
        iyz="0.00"
        izz="0.0001" /> -->
      <inertia
        ixx="0.000190477781556075"
        ixy="-9.83478221577053E-21"
        ixz="1.27384349973246E-20"
        iyy="0.000152318699141993"
        iyz="-8.88301056256029E-06"
        izz="3.93305161229015E-05" />
    </inertial>
    <visual>
      <origin
        xyz="0 0 0"
        rpy="0 0 0" />
      <geometry>
        <mesh
          filename="package://delivery_car/meshes/left_rear_lmount.STL" />
      </geometry>
      <material
        name="">
        <color
          rgba="0.666666666666667 0.698039215686274 0.768627450980392 1" />
      </material>
    </visual>
    <collision>
      <origin
        xyz="0 0 0"
        rpy="0 0 0" />
      <geometry>
        <mesh
          filename="package://delivery_car/meshes/left_rear_lmount.STL" />
      </geometry>
    </collision>
  </link>
  <joint
    name="left_rear_turn_joint"
    type="fixed">
    <origin
      xyz="-0.254 0.2159 0.2794"
      rpy="0 0 0" />
    <parent
      link="base_link" />
    <child
      link="left_rear_lmount" />
    <axis
      xyz="0 0 0" />
  </joint>
  <link
    name="left_rear_wheel">
    <inertial>
      <origin
        xyz="-1.11022302462516E-16 5.59504140230176E-16 -0.0380999999999976"
        rpy="0 0 0" />
      <mass
        value="1.91896102163701" />
      <!-- <inertia
        ixx="0.00592697643071667"
        ixy="-0.00"
        ixz="0.00"
        iyy="0.00592697643071669"
        iyz="0.00"
        izz="0.0100412541412463" /> -->
      <inertia
        ixx="0.00592697643071667"
        ixy="-5.79522737154664E-18"
        ixz="-1.09550633570143E-17"
        iyy="0.00592697643071669"
        iyz="3.549478657157E-17"
        izz="0.0100412541412463" />
      <!-- https://answers.ros.org/question/288237/robot-arm-is-broken-link-by-link-in-gazebo/ -->
    </inertial>
    <visual>
      <origin
        xyz="0 0 0"
        rpy="0 0 0" />
      <geometry>
        <mesh
          filename="package://delivery_car/meshes/left_rear_wheel.STL" />
      </geometry>
      <material
        name="">
        <color
          rgba="0.298039215686275 0.298039215686275 0.298039215686275 1" />
      </material>
    </visual>
    <collision>
      <origin
        xyz="0 0 0"
        rpy="0 0 0" />
      <geometry>
        <mesh
          filename="package://delivery_car/meshes/left_rear_wheel.STL" />
      </geometry>
    </collision>
  </link>

  <joint
    name="left_rear_wheel_joint"
    type="continuous">
    <origin
      xyz="0 0.0381 -0.1778"
      rpy="-1.5707963267949 0 0" />
    <parent
      link="left_rear_lmount" />
    <child
      link="left_rear_wheel" />
    <axis
      xyz="0 0 1" />
  </joint>

  <!-- <joint name="left_rear_wheel_joint" type="revolute">
    <axis xyz="0 0 -1"/>
    <limit effort="1000.0" velocity="20.0"/>
    <origin rpy="-1.5707963267949 0 0" xyz="0 0.0381 -0.1778"/>
    <parent link="left_rear_lmount"/>
    <child link="left_rear_wheel"/>
  </joint> -->

  <transmission name="right_rear_wheel_trans">
    <type>transmission_interface/SimpleTransmission</type>
    <joint name="right_rear_wheel_joint">
      <hardwareInterface>hardware_interface/VelocityJointInterface</hardwareInterface>
    </joint>
    <actuator name="right_rear_wheel_motor">
      <hardwareInterface>hardware_interface/VelocityJointInterface</hardwareInterface>
      <mechanicalReduction>1</mechanicalReduction>
    </actuator>
  </transmission>

  <transmission name="left_rear_wheel_trans">
    <type>transmission_interface/SimpleTransmission</type>
    <joint name="left_rear_wheel_joint">
      <hardwareInterface>hardware_interface/VelocityJointInterface</hardwareInterface>
    </joint>
    <actuator name="left_rear_wheel_motor">
      <hardwareInterface>hardware_interface/VelocityJointInterface</hardwareInterface>
      <mechanicalReduction>1</mechanicalReduction>
    </actuator>
  </transmission>

  <transmission name="right_front_turn_trans">
    <type>transmission_interface/SimpleTransmission</type>
    <joint name="right_front_turn_joint">
      <hardwareInterface>hardware_interface/EffortJointInterface</hardwareInterface>
    </joint>
    <actuator name="right_front_turn_motor">
      <hardwareInterface>hardware_interface/EffortJointInterface</hardwareInterface>
      <mechanicalReduction>1</mechanicalReduction>
    </actuator>
  </transmission> 

  <transmission name="left_front_turn_trans"> 
    <type>transmission_interface/SimpleTransmission</type>
    <joint name="left_front_turn_joint">
      <hardwareInterface>hardware_interface/EffortJointInterface</hardwareInterface>
    </joint>
    <actuator name="left_front_turn_motor">
      <hardwareInterface>hardware_interface/EffortJointInterface</hardwareInterface>
      <mechanicalReduction>1</mechanicalReduction>
    </actuator>
  </transmission>
  
</robot>